<?xml version="1.0" encoding="UTF-8"?>
<testng-results skipped="0" failed="6" total="8" passed="2">
  <reporter-output>
  </reporter-output>
  <suite name="Suite1" duration-ms="40647" started-at="2018-08-29T10:21:19Z" finished-at="2018-08-29T10:22:00Z">
    <groups>
    </groups>
    <test name="ReRun" duration-ms="40615" started-at="2018-08-29T10:21:19Z" finished-at="2018-08-29T10:22:00Z">
      <class name="TestCases.TestReRun">
        <test-method status="PASS" signature="initializeTestBaseSetup(java.lang.reflect.Method)[pri:0, instance:TestCases.TestReRun@4dfa3a9d]" name="initializeTestBaseSetup" is-config="true" duration-ms="9239" started-at="2018-08-29T15:51:19Z" finished-at="2018-08-29T15:51:29Z">
          <params>
            <param index="0">
              <value>
                <![CDATA[public void TestCases.TestReRun.ReRunOne()]]>
              </value>
            </param>
          </params>
          <reporter-output>
          </reporter-output>
        </test-method> <!-- initializeTestBaseSetup -->
        <test-method status="FAIL" signature="ReRunOne()[pri:0, instance:TestCases.TestReRun@4dfa3a9d]" name="ReRunOne" duration-ms="13" started-at="2018-08-29T15:51:29Z" finished-at="2018-08-29T15:51:29Z">
          <exception class="java.lang.AssertionError">
            <message>
              <![CDATA[expected [true] but found [false]]]>
            </message>
            <full-stacktrace>
              <![CDATA[java.lang.AssertionError: expected [true] but found [false]
	at org.testng.Assert.fail(Assert.java:94)
	at org.testng.Assert.failNotEquals(Assert.java:494)
	at org.testng.Assert.assertTrue(Assert.java:42)
	at org.testng.Assert.assertTrue(Assert.java:52)
	at TestCases.TestReRun.ReRunOne(TestReRun.java:13)
	at sun.reflect.NativeMethodAccessorImpl.invoke0(Native Method)
	at sun.reflect.NativeMethodAccessorImpl.invoke(NativeMethodAccessorImpl.java:62)
	at sun.reflect.DelegatingMethodAccessorImpl.invoke(DelegatingMethodAccessorImpl.java:43)
	at java.lang.reflect.Method.invoke(Method.java:498)
	at org.testng.internal.MethodInvocationHelper.invokeMethod(MethodInvocationHelper.java:80)
	at org.testng.internal.Invoker.invokeMethod(Invoker.java:714)
	at org.testng.internal.Invoker.invokeTestMethod(Invoker.java:901)
	at org.testng.internal.Invoker.invokeTestMethods(Invoker.java:1231)
	at org.testng.internal.TestMethodWorker.invokeTestMethods(TestMethodWorker.java:127)
	at org.testng.internal.TestMethodWorker.run(TestMethodWorker.java:111)
	at org.testng.TestRunner.privateRun(TestRunner.java:767)
	at org.testng.TestRunner.run(TestRunner.java:617)
	at org.testng.SuiteRunner.runTest(SuiteRunner.java:334)
	at org.testng.SuiteRunner.runSequentially(SuiteRunner.java:329)
	at org.testng.SuiteRunner.privateRun(SuiteRunner.java:291)
	at org.testng.SuiteRunner.run(SuiteRunner.java:240)
	at org.testng.SuiteRunnerWorker.runSuite(SuiteRunnerWorker.java:52)
	at org.testng.SuiteRunnerWorker.run(SuiteRunnerWorker.java:86)
	at org.testng.TestNG.runSuitesSequentially(TestNG.java:1198)
	at org.testng.TestNG.runSuitesLocally(TestNG.java:1123)
	at org.testng.TestNG.run(TestNG.java:1031)
	at org.testng.remote.AbstractRemoteTestNG.run(AbstractRemoteTestNG.java:114)
	at org.testng.remote.RemoteTestNG.initAndRun(RemoteTestNG.java:251)
	at org.testng.remote.RemoteTestNG.main(RemoteTestNG.java:77)
]]>
            </full-stacktrace>
          </exception> <!-- java.lang.AssertionError -->
          <reporter-output>
          </reporter-output>
        </test-method> <!-- ReRunOne -->
        <test-method status="PASS" signature="afterEachTestMethod(org.testng.ITestResult)[pri:0, instance:TestCases.TestReRun@4dfa3a9d]" name="afterEachTestMethod" is-config="true" duration-ms="1765" started-at="2018-08-29T15:51:29Z" finished-at="2018-08-29T15:51:30Z">
          <params>
            <param index="0">
              <value>
                <![CDATA[[TestResult name=ReRunOne status=FAILURE method=TestReRun.ReRunOne()[pri:0, instance:TestCases.TestReRun@4dfa3a9d] output={null}]]]>
              </value>
            </param>
          </params>
          <reporter-output>
          </reporter-output>
        </test-method> <!-- afterEachTestMethod -->
        <test-method status="PASS" signature="initializeTestBaseSetup(java.lang.reflect.Method)[pri:0, instance:TestCases.TestReRun@4dfa3a9d]" name="initializeTestBaseSetup" is-config="true" duration-ms="7243" started-at="2018-08-29T15:51:30Z" finished-at="2018-08-29T15:51:38Z">
          <params>
            <param index="0">
              <value>
                <![CDATA[public void TestCases.TestReRun.ReRunOne()]]>
              </value>
            </param>
          </params>
          <reporter-output>
          </reporter-output>
        </test-method> <!-- initializeTestBaseSetup -->
        <test-method status="FAIL" signature="ReRunOne()[pri:0, instance:TestCases.TestReRun@4dfa3a9d]" name="ReRunOne" duration-ms="1" started-at="2018-08-29T15:51:38Z" finished-at="2018-08-29T15:51:38Z">
          <exception class="java.lang.AssertionError">
            <message>
              <![CDATA[expected [true] but found [false]]]>
            </message>
            <full-stacktrace>
              <![CDATA[java.lang.AssertionError: expected [true] but found [false]
	at org.testng.Assert.fail(Assert.java:94)
	at org.testng.Assert.failNotEquals(Assert.java:494)
	at org.testng.Assert.assertTrue(Assert.java:42)
	at org.testng.Assert.assertTrue(Assert.java:52)
	at TestCases.TestReRun.ReRunOne(TestReRun.java:13)
	at sun.reflect.NativeMethodAccessorImpl.invoke0(Native Method)
	at sun.reflect.NativeMethodAccessorImpl.invoke(NativeMethodAccessorImpl.java:62)
	at sun.reflect.DelegatingMethodAccessorImpl.invoke(DelegatingMethodAccessorImpl.java:43)
	at java.lang.reflect.Method.invoke(Method.java:498)
	at org.testng.internal.MethodInvocationHelper.invokeMethod(MethodInvocationHelper.java:80)
	at org.testng.internal.Invoker.invokeMethod(Invoker.java:714)
	at org.testng.internal.Invoker.retryFailed(Invoker.java:1049)
	at org.testng.internal.Invoker.invokeTestMethods(Invoker.java:1254)
	at org.testng.internal.TestMethodWorker.invokeTestMethods(TestMethodWorker.java:127)
	at org.testng.internal.TestMethodWorker.run(TestMethodWorker.java:111)
	at org.testng.TestRunner.privateRun(TestRunner.java:767)
	at org.testng.TestRunner.run(TestRunner.java:617)
	at org.testng.SuiteRunner.runTest(SuiteRunner.java:334)
	at org.testng.SuiteRunner.runSequentially(SuiteRunner.java:329)
	at org.testng.SuiteRunner.privateRun(SuiteRunner.java:291)
	at org.testng.SuiteRunner.run(SuiteRunner.java:240)
	at org.testng.SuiteRunnerWorker.runSuite(SuiteRunnerWorker.java:52)
	at org.testng.SuiteRunnerWorker.run(SuiteRunnerWorker.java:86)
	at org.testng.TestNG.runSuitesSequentially(TestNG.java:1198)
	at org.testng.TestNG.runSuitesLocally(TestNG.java:1123)
	at org.testng.TestNG.run(TestNG.java:1031)
	at org.testng.remote.AbstractRemoteTestNG.run(AbstractRemoteTestNG.java:114)
	at org.testng.remote.RemoteTestNG.initAndRun(RemoteTestNG.java:251)
	at org.testng.remote.RemoteTestNG.main(RemoteTestNG.java:77)
]]>
            </full-stacktrace>
          </exception> <!-- java.lang.AssertionError -->
          <reporter-output>
          </reporter-output>
        </test-method> <!-- ReRunOne -->
        <test-method status="PASS" signature="afterEachTestMethod(org.testng.ITestResult)[pri:0, instance:TestCases.TestReRun@4dfa3a9d]" name="afterEachTestMethod" is-config="true" duration-ms="1426" started-at="2018-08-29T15:51:38Z" finished-at="2018-08-29T15:51:39Z">
          <params>
            <param index="0">
              <value>
                <![CDATA[[TestResult name=ReRunOne status=FAILURE method=TestReRun.ReRunOne()[pri:0, instance:TestCases.TestReRun@4dfa3a9d] output={null}]]]>
              </value>
            </param>
          </params>
          <reporter-output>
          </reporter-output>
        </test-method> <!-- afterEachTestMethod -->
        <test-method status="PASS" signature="initializeTestBaseSetup(java.lang.reflect.Method)[pri:0, instance:TestCases.TestReRun@4dfa3a9d]" name="initializeTestBaseSetup" is-config="true" duration-ms="7727" started-at="2018-08-29T15:51:39Z" finished-at="2018-08-29T15:51:47Z">
          <params>
            <param index="0">
              <value>
                <![CDATA[public void TestCases.TestReRun.ReRunOne()]]>
              </value>
            </param>
          </params>
          <reporter-output>
          </reporter-output>
        </test-method> <!-- initializeTestBaseSetup -->
        <test-method status="FAIL" signature="ReRunOne()[pri:0, instance:TestCases.TestReRun@4dfa3a9d]" name="ReRunOne" duration-ms="1" started-at="2018-08-29T15:51:47Z" finished-at="2018-08-29T15:51:47Z">
          <exception class="java.lang.AssertionError">
            <message>
              <![CDATA[expected [true] but found [false]]]>
            </message>
            <full-stacktrace>
              <![CDATA[java.lang.AssertionError: expected [true] but found [false]
	at org.testng.Assert.fail(Assert.java:94)
	at org.testng.Assert.failNotEquals(Assert.java:494)
	at org.testng.Assert.assertTrue(Assert.java:42)
	at org.testng.Assert.assertTrue(Assert.java:52)
	at TestCases.TestReRun.ReRunOne(TestReRun.java:13)
	at sun.reflect.NativeMethodAccessorImpl.invoke0(Native Method)
	at sun.reflect.NativeMethodAccessorImpl.invoke(NativeMethodAccessorImpl.java:62)
	at sun.reflect.DelegatingMethodAccessorImpl.invoke(DelegatingMethodAccessorImpl.java:43)
	at java.lang.reflect.Method.invoke(Method.java:498)
	at org.testng.internal.MethodInvocationHelper.invokeMethod(MethodInvocationHelper.java:80)
	at org.testng.internal.Invoker.invokeMethod(Invoker.java:714)
	at org.testng.internal.Invoker.retryFailed(Invoker.java:1049)
	at org.testng.internal.Invoker.invokeTestMethods(Invoker.java:1254)
	at org.testng.internal.TestMethodWorker.invokeTestMethods(TestMethodWorker.java:127)
	at org.testng.internal.TestMethodWorker.run(TestMethodWorker.java:111)
	at org.testng.TestRunner.privateRun(TestRunner.java:767)
	at org.testng.TestRunner.run(TestRunner.java:617)
	at org.testng.SuiteRunner.runTest(SuiteRunner.java:334)
	at org.testng.SuiteRunner.runSequentially(SuiteRunner.java:329)
	at org.testng.SuiteRunner.privateRun(SuiteRunner.java:291)
	at org.testng.SuiteRunner.run(SuiteRunner.java:240)
	at org.testng.SuiteRunnerWorker.runSuite(SuiteRunnerWorker.java:52)
	at org.testng.SuiteRunnerWorker.run(SuiteRunnerWorker.java:86)
	at org.testng.TestNG.runSuitesSequentially(TestNG.java:1198)
	at org.testng.TestNG.runSuitesLocally(TestNG.java:1123)
	at org.testng.TestNG.run(TestNG.java:1031)
	at org.testng.remote.AbstractRemoteTestNG.run(AbstractRemoteTestNG.java:114)
	at org.testng.remote.RemoteTestNG.initAndRun(RemoteTestNG.java:251)
	at org.testng.remote.RemoteTestNG.main(RemoteTestNG.java:77)
]]>
            </full-stacktrace>
          </exception> <!-- java.lang.AssertionError -->
          <reporter-output>
          </reporter-output>
        </test-method> <!-- ReRunOne -->
        <test-method status="PASS" signature="afterEachTestMethod(org.testng.ITestResult)[pri:0, instance:TestCases.TestReRun@4dfa3a9d]" name="afterEachTestMethod" is-config="true" duration-ms="1416" started-at="2018-08-29T15:51:47Z" finished-at="2018-08-29T15:51:48Z">
          <params>
            <param index="0">
              <value>
                <![CDATA[[TestResult name=ReRunOne status=FAILURE method=TestReRun.ReRunOne()[pri:0, instance:TestCases.TestReRun@4dfa3a9d] output={null}]]]>
              </value>
            </param>
          </params>
          <reporter-output>
          </reporter-output>
        </test-method> <!-- afterEachTestMethod -->
        <test-method status="PASS" signature="initializeTestBaseSetup(java.lang.reflect.Method)[pri:0, instance:TestCases.TestReRun@4dfa3a9d]" name="initializeTestBaseSetup" is-config="true" duration-ms="7511" started-at="2018-08-29T15:51:48Z" finished-at="2018-08-29T15:51:56Z">
          <params>
            <param index="0">
              <value>
                <![CDATA[public void TestCases.TestReRun.ReRuntwo()]]>
              </value>
            </param>
          </params>
          <reporter-output>
          </reporter-output>
        </test-method> <!-- initializeTestBaseSetup -->
        <test-method status="PASS" signature="ReRuntwo()[pri:0, instance:TestCases.TestReRun@4dfa3a9d]" name="ReRuntwo" duration-ms="1" started-at="2018-08-29T15:51:56Z" finished-at="2018-08-29T15:51:56Z">
          <reporter-output>
          </reporter-output>
        </test-method> <!-- ReRuntwo -->
        <test-method status="PASS" signature="afterEachTestMethod(org.testng.ITestResult)[pri:0, instance:TestCases.TestReRun@4dfa3a9d]" name="afterEachTestMethod" is-config="true" duration-ms="4262" started-at="2018-08-29T15:51:56Z" finished-at="2018-08-29T15:52:00Z">
          <params>
            <param index="0">
              <value>
                <![CDATA[[TestResult name=ReRuntwo status=SUCCESS method=TestReRun.ReRuntwo()[pri:0, instance:TestCases.TestReRun@4dfa3a9d] output={null}]]]>
              </value>
            </param>
          </params>
          <reporter-output>
          </reporter-output>
        </test-method> <!-- afterEachTestMethod -->
      </class> <!-- TestCases.TestReRun -->
    </test> <!-- ReRun -->
    <test name="AnotherReRun" duration-ms="0" started-at="2018-08-29T10:22:00Z" finished-at="2018-08-29T10:22:00Z">
      <class name="TestCases.TestingAgainRun">
        <test-method status="FAIL" signature="ReRunningTwo()[pri:0, instance:TestCases.TestingAgainRun@56ef9176]" name="ReRunningTwo" duration-ms="0" started-at="2018-08-29T15:52:00Z" finished-at="2018-08-29T15:52:00Z">
          <exception class="java.lang.AssertionError">
            <message>
              <![CDATA[expected [true] but found [false]]]>
            </message>
            <full-stacktrace>
              <![CDATA[java.lang.AssertionError: expected [true] but found [false]
	at org.testng.Assert.fail(Assert.java:94)
	at org.testng.Assert.failNotEquals(Assert.java:494)
	at org.testng.Assert.assertTrue(Assert.java:42)
	at org.testng.Assert.assertTrue(Assert.java:52)
	at TestCases.TestingAgainRun.ReRunningTwo(TestingAgainRun.java:18)
	at sun.reflect.NativeMethodAccessorImpl.invoke0(Native Method)
	at sun.reflect.NativeMethodAccessorImpl.invoke(NativeMethodAccessorImpl.java:62)
	at sun.reflect.DelegatingMethodAccessorImpl.invoke(DelegatingMethodAccessorImpl.java:43)
	at java.lang.reflect.Method.invoke(Method.java:498)
	at org.testng.internal.MethodInvocationHelper.invokeMethod(MethodInvocationHelper.java:80)
	at org.testng.internal.Invoker.invokeMethod(Invoker.java:714)
	at org.testng.internal.Invoker.invokeTestMethod(Invoker.java:901)
	at org.testng.internal.Invoker.invokeTestMethods(Invoker.java:1231)
	at org.testng.internal.TestMethodWorker.invokeTestMethods(TestMethodWorker.java:127)
	at org.testng.internal.TestMethodWorker.run(TestMethodWorker.java:111)
	at org.testng.TestRunner.privateRun(TestRunner.java:767)
	at org.testng.TestRunner.run(TestRunner.java:617)
	at org.testng.SuiteRunner.runTest(SuiteRunner.java:334)
	at org.testng.SuiteRunner.runSequentially(SuiteRunner.java:329)
	at org.testng.SuiteRunner.privateRun(SuiteRunner.java:291)
	at org.testng.SuiteRunner.run(SuiteRunner.java:240)
	at org.testng.SuiteRunnerWorker.runSuite(SuiteRunnerWorker.java:52)
	at org.testng.SuiteRunnerWorker.run(SuiteRunnerWorker.java:86)
	at org.testng.TestNG.runSuitesSequentially(TestNG.java:1198)
	at org.testng.TestNG.runSuitesLocally(TestNG.java:1123)
	at org.testng.TestNG.run(TestNG.java:1031)
	at org.testng.remote.AbstractRemoteTestNG.run(AbstractRemoteTestNG.java:114)
	at org.testng.remote.RemoteTestNG.initAndRun(RemoteTestNG.java:251)
	at org.testng.remote.RemoteTestNG.main(RemoteTestNG.java:77)
]]>
            </full-stacktrace>
          </exception> <!-- java.lang.AssertionError -->
          <reporter-output>
          </reporter-output>
        </test-method> <!-- ReRunningTwo -->
        <test-method status="FAIL" signature="ReRunningTwo()[pri:0, instance:TestCases.TestingAgainRun@56ef9176]" name="ReRunningTwo" duration-ms="0" started-at="2018-08-29T15:52:00Z" finished-at="2018-08-29T15:52:00Z">
          <exception class="java.lang.AssertionError">
            <message>
              <![CDATA[expected [true] but found [false]]]>
            </message>
            <full-stacktrace>
              <![CDATA[java.lang.AssertionError: expected [true] but found [false]
	at org.testng.Assert.fail(Assert.java:94)
	at org.testng.Assert.failNotEquals(Assert.java:494)
	at org.testng.Assert.assertTrue(Assert.java:42)
	at org.testng.Assert.assertTrue(Assert.java:52)
	at TestCases.TestingAgainRun.ReRunningTwo(TestingAgainRun.java:18)
	at sun.reflect.NativeMethodAccessorImpl.invoke0(Native Method)
	at sun.reflect.NativeMethodAccessorImpl.invoke(NativeMethodAccessorImpl.java:62)
	at sun.reflect.DelegatingMethodAccessorImpl.invoke(DelegatingMethodAccessorImpl.java:43)
	at java.lang.reflect.Method.invoke(Method.java:498)
	at org.testng.internal.MethodInvocationHelper.invokeMethod(MethodInvocationHelper.java:80)
	at org.testng.internal.Invoker.invokeMethod(Invoker.java:714)
	at org.testng.internal.Invoker.retryFailed(Invoker.java:1049)
	at org.testng.internal.Invoker.invokeTestMethods(Invoker.java:1254)
	at org.testng.internal.TestMethodWorker.invokeTestMethods(TestMethodWorker.java:127)
	at org.testng.internal.TestMethodWorker.run(TestMethodWorker.java:111)
	at org.testng.TestRunner.privateRun(TestRunner.java:767)
	at org.testng.TestRunner.run(TestRunner.java:617)
	at org.testng.SuiteRunner.runTest(SuiteRunner.java:334)
	at org.testng.SuiteRunner.runSequentially(SuiteRunner.java:329)
	at org.testng.SuiteRunner.privateRun(SuiteRunner.java:291)
	at org.testng.SuiteRunner.run(SuiteRunner.java:240)
	at org.testng.SuiteRunnerWorker.runSuite(SuiteRunnerWorker.java:52)
	at org.testng.SuiteRunnerWorker.run(SuiteRunnerWorker.java:86)
	at org.testng.TestNG.runSuitesSequentially(TestNG.java:1198)
	at org.testng.TestNG.runSuitesLocally(TestNG.java:1123)
	at org.testng.TestNG.run(TestNG.java:1031)
	at org.testng.remote.AbstractRemoteTestNG.run(AbstractRemoteTestNG.java:114)
	at org.testng.remote.RemoteTestNG.initAndRun(RemoteTestNG.java:251)
	at org.testng.remote.RemoteTestNG.main(RemoteTestNG.java:77)
]]>
            </full-stacktrace>
          </exception> <!-- java.lang.AssertionError -->
          <reporter-output>
          </reporter-output>
        </test-method> <!-- ReRunningTwo -->
        <test-method status="PASS" signature="ReRunningOne()[pri:0, instance:TestCases.TestingAgainRun@56ef9176]" name="ReRunningOne" duration-ms="0" started-at="2018-08-29T15:52:00Z" finished-at="2018-08-29T15:52:00Z">
          <reporter-output>
          </reporter-output>
        </test-method> <!-- ReRunningOne -->
        <test-method status="FAIL" signature="ReRunningTwo()[pri:0, instance:TestCases.TestingAgainRun@56ef9176]" name="ReRunningTwo" duration-ms="0" started-at="2018-08-29T15:52:00Z" finished-at="2018-08-29T15:52:00Z">
          <exception class="java.lang.AssertionError">
            <message>
              <![CDATA[expected [true] but found [false]]]>
            </message>
            <full-stacktrace>
              <![CDATA[java.lang.AssertionError: expected [true] but found [false]
	at org.testng.Assert.fail(Assert.java:94)
	at org.testng.Assert.failNotEquals(Assert.java:494)
	at org.testng.Assert.assertTrue(Assert.java:42)
	at org.testng.Assert.assertTrue(Assert.java:52)
	at TestCases.TestingAgainRun.ReRunningTwo(TestingAgainRun.java:18)
	at sun.reflect.NativeMethodAccessorImpl.invoke0(Native Method)
	at sun.reflect.NativeMethodAccessorImpl.invoke(NativeMethodAccessorImpl.java:62)
	at sun.reflect.DelegatingMethodAccessorImpl.invoke(DelegatingMethodAccessorImpl.java:43)
	at java.lang.reflect.Method.invoke(Method.java:498)
	at org.testng.internal.MethodInvocationHelper.invokeMethod(MethodInvocationHelper.java:80)
	at org.testng.internal.Invoker.invokeMethod(Invoker.java:714)
	at org.testng.internal.Invoker.retryFailed(Invoker.java:1049)
	at org.testng.internal.Invoker.invokeTestMethods(Invoker.java:1254)
	at org.testng.internal.TestMethodWorker.invokeTestMethods(TestMethodWorker.java:127)
	at org.testng.internal.TestMethodWorker.run(TestMethodWorker.java:111)
	at org.testng.TestRunner.privateRun(TestRunner.java:767)
	at org.testng.TestRunner.run(TestRunner.java:617)
	at org.testng.SuiteRunner.runTest(SuiteRunner.java:334)
	at org.testng.SuiteRunner.runSequentially(SuiteRunner.java:329)
	at org.testng.SuiteRunner.privateRun(SuiteRunner.java:291)
	at org.testng.SuiteRunner.run(SuiteRunner.java:240)
	at org.testng.SuiteRunnerWorker.runSuite(SuiteRunnerWorker.java:52)
	at org.testng.SuiteRunnerWorker.run(SuiteRunnerWorker.java:86)
	at org.testng.TestNG.runSuitesSequentially(TestNG.java:1198)
	at org.testng.TestNG.runSuitesLocally(TestNG.java:1123)
	at org.testng.TestNG.run(TestNG.java:1031)
	at org.testng.remote.AbstractRemoteTestNG.run(AbstractRemoteTestNG.java:114)
	at org.testng.remote.RemoteTestNG.initAndRun(RemoteTestNG.java:251)
	at org.testng.remote.RemoteTestNG.main(RemoteTestNG.java:77)
]]>
            </full-stacktrace>
          </exception> <!-- java.lang.AssertionError -->
          <reporter-output>
          </reporter-output>
        </test-method> <!-- ReRunningTwo -->
      </class> <!-- TestCases.TestingAgainRun -->
      <class name="Utility.Base">
        <test-method status="PASS" signature="extentSetup(org.testng.ITestContext)[pri:0, instance:Utility.Base@4566e5bd]" name="extentSetup" is-config="true" duration-ms="250" started-at="2018-08-29T15:51:19Z" finished-at="2018-08-29T15:51:19Z">
          <params>
            <param index="0">
              <value>
                <![CDATA[org.testng.TestRunner@765f05af]]>
              </value>
            </param>
          </params>
          <reporter-output>
          </reporter-output>
        </test-method> <!-- extentSetup -->
        <test-method status="PASS" signature="generateReport()[pri:0, instance:Utility.Base@4566e5bd]" name="generateReport" is-config="true" duration-ms="0" started-at="2018-08-29T15:52:00Z" finished-at="2018-08-29T15:52:00Z">
          <reporter-output>
          </reporter-output>
        </test-method> <!-- generateReport -->
      </class> <!-- Utility.Base -->
    </test> <!-- AnotherReRun -->
  </suite> <!-- Suite1 -->
</testng-results>
